<?xml version="1.0" ?>
<robot name="stretch_description" version="1.0">
    <link name="link_gripper">
        
<inertial>
            <origin rpy="0.0 0.0 0.0" xyz="-0.017022913273 0.0131410320934 -0.0371614759485" />
            <mass value="0.101902711393" />
            <inertia ixx="0.001" ixy="0.0" ixz="0.0" iyy="0.001" iyz="0.0" izz="0.001" />
        </inertial>

        <visual>
            <origin rpy="0.0 0.0 0.0" xyz="0.0 0.0 0.0" />
            <geometry>
                <mesh filename="package://stretch_description/meshes/link_gripper.STL" />
            </geometry>
            <material name="">
                <color rgba="0.792156862745 0.819607843137 0.933333333333 1.0" />
            </material>
        </visual>
        <collision>
            <origin rpy="0.0 0.0 0.0" xyz="0.0 0.0 0.0" />
            <geometry>
                <mesh filename="package://stretch_description/meshes/link_gripper.STL" />
            </geometry>
        </collision>
    </link>
    <joint name="joint_gripper" type="fixed">
        <origin rpy="3.14159 0.0 -1.5708" xyz="0.0 0.0 0.0" />
        <axis xyz="0.0 0.0 0.0" />
        <parent link="link_wrist_yaw" />
        <child link="link_gripper" />
    </joint>
    <link name="link_gripper_finger_left">
        
<inertial>
            <origin rpy="0.0 0.0 0.0" xyz="0.094504748351 0.0124301080924 -4.4408920985e-16" />
            <mass value="0.0476207785199" />
            <inertia ixx="0.001" ixy="0.0" ixz="0.0" iyy="0.001" iyz="0.0" izz="0.001" />
        </inertial>

        <visual>
            <origin rpy="0.0 0.0 0.0" xyz="0.0 0.0 0.0" />
            <geometry>
                <mesh filename="package://stretch_description/meshes/link_gripper_finger_left.STL" scale="0.9 1.0 1.0" />
            </geometry>
            <material name="">
                <color rgba="0.792156862745 0.819607843137 0.933333333333 1.0" />
            </material>
        </visual>
        <collision>
            <origin rpy="0.0 0.0 0.0" xyz="0.0 0.0 0.0" />
            <geometry>
                <mesh filename="package://stretch_description/meshes/link_gripper_finger_left.STL" scale="0.9 1.0 1.0" />
            </geometry>
        </collision>
    </link>
    <joint name="joint_gripper_finger_left" type="revolute">
        <origin rpy="2.1762e-15 0.5236 3.1416" xyz="-0.047231 -0.010151 -0.04679" />
        <axis xyz="0.0 0.0 1.0" />
        <parent link="link_gripper" />
        <child link="link_gripper_finger_left" />
        <limit effort="100.0" lower="-0.6" upper="0.6" velocity="1.0" />
    </joint>
    <link name="link_gripper_fingertip_left">
        
<inertial>
            <origin rpy="0.0 0.0 0.0" xyz="-3.16381381649e-08 -2.91408530639e-09 0.00812579670382" />
            <mass value="0.00382159917456" />
            <inertia ixx="0.001" ixy="0.0" ixz="0.0" iyy="0.001" iyz="0.0" izz="0.001" />
        </inertial>

        <visual>
            <origin rpy="0.0 0.0 0.0" xyz="0.0 0.0 0.0" />
            <geometry>
                <mesh filename="package://stretch_description/meshes/link_gripper_fingertip_left.STL" />
            </geometry>
            <material name="">
                <color rgba="0.250980392157 0.250980392157 0.250980392157 1.0" />
            </material>
        </visual>
        <collision>
            <origin rpy="0.0 0.0 0.0" xyz="0.0 0.0 0.0" />
            <geometry>
                <mesh filename="package://stretch_description/meshes/link_gripper_fingertip_left.STL" />
            </geometry>
        </collision>
    </link>
    <joint name="joint_gripper_fingertip_left" type="fixed">
        <origin rpy="-1.5708 -4.774e-15 -2.5545" xyz="0.171099 0.014912 0.0" />
        <axis xyz="0.0 0.0 0.0" />
        <parent link="link_gripper_finger_left" />
        <child link="link_gripper_fingertip_left" />
    </joint>
    <link name="link_gripper_finger_right">
        
<inertial>
            <origin rpy="0.0 0.0 0.0" xyz="-0.094504748351 -0.0124301080924 0.0" />
            <mass value="0.0476207785199" />
            <inertia ixx="0.001" ixy="0.0" ixz="0.0" iyy="0.001" iyz="0.0" izz="0.001" />
        </inertial>

        <visual>
            <origin rpy="0.0 0.0 0.0" xyz="0.0 0.0 0.0" />
            <geometry>
                <mesh filename="package://stretch_description/meshes/link_gripper_finger_right.STL" scale="0.9 1.0 1.0" />
            </geometry>
            <material name="">
                <color rgba="0.792156862745 0.819607843137 0.933333333333 1.0" />
            </material>
        </visual>
        <collision>
            <origin rpy="0.0 0.0 0.0" xyz="0.0 0.0 0.0" />
            <geometry>
                <mesh filename="package://stretch_description/meshes/link_gripper_finger_right.STL" scale="0.9 1.0 1.0" />
            </geometry>
        </collision>
    </link>
    <joint name="joint_gripper_finger_right" type="revolute">
        <origin rpy="3.1416 -0.5236 1.2943e-15" xyz="-0.047231 0.010049 -0.04679" />
        <axis xyz="0.0 0.0 1.0" />
        <parent link="link_gripper" />
        <child link="link_gripper_finger_right" />
        <limit effort="100.0" lower="-0.6" upper="0.6" velocity="1.0" />
    </joint>
    <link name="link_gripper_fingertip_right">
        
<inertial>
            <origin rpy="0.0 0.0 0.0" xyz="2.59386303963e-08 6.70949018566e-09 0.0081257951613" />
            <mass value="0.0038216003732" />
            <inertia ixx="0.001" ixy="0.0" ixz="0.0" iyy="0.001" iyz="0.0" izz="0.001" />
        </inertial>

        <visual>
            <origin rpy="0.0 0.0 0.0" xyz="0.0 0.0 0.0" />
            <geometry>
                <mesh filename="package://stretch_description/meshes/link_gripper_fingertip_right.STL" />
            </geometry>
            <material name="">
                <color rgba="0.250980392157 0.250980392157 0.250980392157 1.0" />
            </material>
        </visual>
        <collision>
            <origin rpy="0.0 0.0 0.0" xyz="0.0 0.0 0.0" />
            <geometry>
                <mesh filename="package://stretch_description/meshes/link_gripper_fingertip_right.STL" />
            </geometry>
        </collision>
    </link>
    <joint name="joint_gripper_fingertip_right" type="fixed">
        <origin rpy="-1.5708 -2.0539e-15 0.58705" xyz="-0.171099 -0.014912 0.0" />
        <axis xyz="0.0 0.0 0.0" />
        <parent link="link_gripper_finger_right" />
        <child link="link_gripper_fingertip_right" />
    </joint>
    <link name="link_grasp_center" />
    <joint name="joint_grasp_center" type="fixed">
        <origin rpy="0.0 0.0 3.141579" xyz="-0.205478 0.0 -0.138154" />
        <parent link="link_gripper" />
        <child link="link_grasp_center" />
    </joint>
    <link name="base_link">
        
<inertial>
            <origin rpy="0.0 0.0 0.0" xyz="-0.109461304328 -0.000741018909048 0.091491526943" />
            <mass value="1.07237826598" />
            <inertia ixx="0.0031058090771" ixy="1.51828481911e-06" ixz="0.000416904667324" iyy="0.00433798719992" iyz="1.33487716258e-05" izz="0.00372047274674" />
        </inertial>

        <visual>
            <origin rpy="0.0 0.0 0.0" xyz="0.0 0.0 0.0" />
            <geometry>
                <mesh filename="package://stretch_description/meshes/base_link.STL" />
            </geometry>
            <material name="">
                <color rgba="0.792156862745 0.819607843137 0.933333333333 1.0" />
            </material>
        </visual>
        <collision>
            <origin rpy="0.0 0.0 0.0" xyz="0.0 0.0 0.0" />
            <geometry>
                <mesh filename="package://stretch_description/meshes/base_link.STL" />
            </geometry>
        </collision>
    </link>
    <link name="link_right_wheel">
        
<inertial>
            <origin rpy="0.0 0.0 0.0" xyz="1.25554620867e-07 3.54748938447e-07 0.0239581106165" />
            <mass value="0.01" />
            <inertia ixx="0.001" ixy="0.0" ixz="0.0" iyy="0.001" iyz="0.0" izz="0.001" />
        </inertial>

        <visual>
            <origin rpy="0.0 0.0 0.0" xyz="0.0 0.0 0.0" />
            <geometry>
                <mesh filename="package://stretch_description/meshes/link_right_wheel.STL" />
            </geometry>
            <material name="">
                <color rgba="0.792156862745 0.819607843137 0.933333333333 1.0" />
            </material>
        </visual>
        <collision>
            <origin rpy="0.0 0.0 0.0" xyz="0.0 0.0 0.0" />
            <geometry>
                <mesh filename="package://stretch_description/meshes/link_right_wheel.STL" />
            </geometry>
        </collision>
    </link>
    <joint name="joint_right_wheel" type="continuous">
        <origin rpy="-1.57079632679 -1.11022302463e-16 7.2858385991e-17" xyz="-0.003 -0.15765 0.0508" />
        <axis xyz="0.0 0.0 1.0" />
        <parent link="base_link" />
        <child link="link_right_wheel" />
        <dynamics damping="21.75" friction="10.48" />
    </joint>
    <link name="link_left_wheel">
        
<inertial>
            <origin rpy="0.0 0.0 0.0" xyz="1.25554620922e-07 -3.54748938503e-07 -0.0239581106165" />
            <mass value="0.01" />
            <inertia ixx="0.001" ixy="0.0" ixz="0.0" iyy="0.001" iyz="0.0" izz="0.001" />
        </inertial>

        <visual>
            <origin rpy="0.0 0.0 0.0" xyz="0.0 0.0 0.0" />
            <geometry>
                <mesh filename="package://stretch_description/meshes/link_left_wheel.STL" />
            </geometry>
            <material name="">
                <color rgba="0.792156862745 0.819607843137 0.933333333333 1.0" />
            </material>
        </visual>
        <collision>
            <origin rpy="0.0 0.0 0.0" xyz="0.0 0.0 0.0" />
            <geometry>
                <mesh filename="package://stretch_description/meshes/link_left_wheel.STL" />
            </geometry>
        </collision>
    </link>
    <joint name="joint_left_wheel" type="continuous">
        <origin rpy="-1.57079632679 3.16227047921e-31 7.88745438254e-16" xyz="-0.00300000000002 0.15765 0.0508" />
        <axis xyz="0.0 0.0 1.0" />
        <parent link="base_link" />
        <child link="link_left_wheel" />
        <dynamics damping="21.75" friction="10.48" />
    </joint>
    <link name="caster_link">
        
<inertial>
            <origin rpy="0 0 0" xyz="0.0 0.0 0.0" />
            <mass value="0.01" />
            <inertia ixx="0.001" ixy="0.0" ixz="0.0" iyy="0.001" iyz="0.0" izz="0.001" />
        </inertial>

        <collision>
            <origin rpy="0.0 0.0 0.0" xyz="0.0 0.0 0.0" />
            <geometry>
                <sphere radius="0.032" />
            </geometry>
        </collision>
        <visual>
            <origin rpy="0.0 0.0 0.0" xyz="0.0 0.0 0.0" />
            <geometry>
                <mesh filename="package://stretch_description/meshes/omni_wheel_m.STL" />
            </geometry>
            <material name="">
                <color rgba="0.792156862745 0.819607843137 0.933333333333 1.0" />
            </material>
        </visual>
    </link>
    <joint name="caster_joint" type="fixed">
        <origin rpy="-1.57079632679 0.0 0.0" xyz="-0.245 0.0 0.032" />
        <axis xyz="0.0 0.0 1.0" />
        <parent link="base_link" />
        <child link="caster_link" />
    </joint>
    <link name="link_mast">
        
<inertial>
            <origin rpy="0.0 0.0 0.0" xyz="0.00755818572976 0.773971284177 0.0064731308662" />
            <mass value="0.749143203376" />
            <inertia ixx="0.0709854511955" ixy="-0.00433428742758" ixz="-0.000186110788698" iyy="0.000437922053343" iyz="-0.00288788257713" izz="0.0711048085017" />
        </inertial>

        <visual>
            <origin rpy="0.0 0.0 0.0" xyz="0.0 0.0 0.0" />
            <geometry>
                <mesh filename="package://stretch_description/meshes/link_mast.STL" />
            </geometry>
            <material name="">
                <color rgba="0.792156862745 0.819607843137 0.933333333333 1.0" />
            </material>
        </visual>
        <collision>
            <origin rpy="0.0 0.0 0.0" xyz="0.0 0.0 0.0" />
            <geometry>
                <mesh filename="package://stretch_description/meshes/link_mast.STL" />
            </geometry>
        </collision>
    </link>
    <joint name="joint_mast" type="fixed">
        <origin rpy="1.5590397612212408 0.023427641144290412 0.006739448561568549" xyz="-0.07387773964359509 0.13783243762213837 0.03235333347342398" />
        <axis xyz="0.0 0.0 0.0" />
        <parent link="base_link" />
        <child link="link_mast" />
    </joint>
    <link name="link_lift">
        
<inertial>
            <origin rpy="0.0 0.0 0.0" xyz="-0.0547636346253 0.0380939689802 0.00933159404448" />
            <mass value="0.444820831236" />
            <inertia ixx="0.000567192946271" ixy="-0.000246075347895" ixz="-0.000128108442261" iyy="0.00127108364479" iyz="7.6191685507e-06" izz="0.00137296635099" />
        </inertial>

        <visual>
            <origin rpy="0.0 0.0 0.0" xyz="0.0 0.0 0.0" />
            <geometry>
                <mesh filename="package://stretch_description/meshes/link_lift.STL" />
            </geometry>
            <material name="">
                <color rgba="0.792156862745 0.819607843137 0.933333333333 1.0" />
            </material>
        </visual>
        <collision>
            <origin rpy="0.0 0.0 0.0" xyz="0.0 0.0 0.0" />
            <geometry>
                <mesh filename="package://stretch_description/meshes/link_lift.STL" />
            </geometry>
        </collision>
    </link>
    <joint name="joint_lift" type="prismatic">
        <origin rpy="-1.5707963268 1.56154313753 -6.29420043665e-13" xyz="-0.0369217062323 0.1654712 -0.000341653286794" />
        <axis xyz="0.0 0.0 1.0" />
        <parent link="link_mast" />
        <child link="link_lift" />
        <limit effort="100.0" lower="0.0" upper="1.1" velocity="1.0" />
    </joint>
    <link name="link_arm_l4">
        
<inertial>
            <origin rpy="0.0 0.0 0.0" xyz="-1.61247276464e-06 1.54715589201e-06 -0.095325270604" />
            <mass value="0.067652545579" />
            <inertia ixx="0.000122002023067" ixy="7.2959335623e-13" ixz="9.63170353371e-09" iyy="0.000122002023127" iyz="-9.24154949889e-09" izz="1.4604343981e-12" />
        </inertial>

        <visual>
            <origin rpy="0.0 0.0 0.0" xyz="0.0 0.0 0.0" />
            <geometry>
                <mesh filename="package://stretch_description/meshes/link_arm_l4.STL" />
            </geometry>
            <material name="">
                <color rgba="0.792156862745 0.819607843137 0.933333333333 1.0" />
            </material>
        </visual>
        <collision>
            <origin rpy="0.0 0.0 0.0" xyz="0.0 0.0 0.0" />
            <geometry>
                <mesh filename="package://stretch_description/meshes/link_arm_l4.STL" />
            </geometry>
        </collision>
    </link>
    <joint name="joint_arm_l4" type="fixed">
        <origin rpy="1.5706370742481743 -0.04861394029305366 -1.5999203239650384" xyz="-0.26004302676731866 -0.005686684848839391 -0.004811536075100588" />
        <axis xyz="0.0 0.0 0.0" />
        <parent link="link_lift" />
        <child link="link_arm_l4" />
    </joint>
    <link name="link_arm_l3">
        
<inertial>
            <origin rpy="0.0 0.0 0.0" xyz="-3.34873468621e-07 4.74113363069e-07 -0.0974069598289" />
            <mass value="0.0626921047058" />
            <inertia ixx="0.001" ixy="0.0" ixz="0.0" iyy="0.001" iyz="0.0" izz="0.001" />
        </inertial>

        <visual>
            <origin rpy="0.0 0.0 0.0" xyz="0.0 0.0 0.0" />
            <geometry>
                <mesh filename="package://stretch_description/meshes/link_arm_l3.STL" />
            </geometry>
            <material name="">
                <color rgba="0.792156862745 0.819607843137 0.933333333333 1.0" />
            </material>
        </visual>
        <collision>
            <origin rpy="0.0 0.0 0.0" xyz="0.0 0.0 0.0" />
            <geometry>
                <mesh filename="package://stretch_description/meshes/link_arm_l3.STL" />
            </geometry>
        </collision>
    </link>
    <joint name="joint_arm_l3" type="prismatic">
        <origin rpy="3.5742e-16 3.2123e-16 -2.4565e-16" xyz="0.0 0.0 0.013" />
        <axis xyz="0.0 0.0 1.0" />
        <parent link="link_arm_l4" />
        <child link="link_arm_l3" />
        <limit effort="100.0" lower="0.0" upper="0.13" velocity="1.0" />
    </joint>
    <link name="link_arm_l2">
        
<inertial>
            <origin rpy="0.0 0.0 0.0" xyz="-3.31043560509e-07 3.13422303999e-07 -0.0972558835419" />
            <mass value="0.0569074368576" />
            <inertia ixx="0.001" ixy="0.0" ixz="0.0" iyy="0.001" iyz="0.0" izz="0.001" />
        </inertial>

        <visual>
            <origin rpy="0.0 0.0 0.0" xyz="0.0 0.0 0.0" />
            <geometry>
                <mesh filename="package://stretch_description/meshes/link_arm_l2.STL" />
            </geometry>
            <material name="">
                <color rgba="0.792156862745 0.819607843137 0.933333333333 1.0" />
            </material>
        </visual>
        <collision>
            <origin rpy="0.0 0.0 0.0" xyz="0.0 0.0 0.0" />
            <geometry>
                <mesh filename="package://stretch_description/meshes/link_arm_l2.STL" />
            </geometry>
        </collision>
    </link>
    <joint name="joint_arm_l2" type="prismatic">
        <origin rpy="2.91385731014e-16 4.44300759505e-17 3.25691080516e-16" xyz="0.0 0.0 0.013" />
        <axis xyz="0.0 0.0 1.0" />
        <parent link="link_arm_l3" />
        <child link="link_arm_l2" />
        <limit effort="100.0" lower="0.0" upper="0.13" velocity="1.0" />
    </joint>
    <link name="link_arm_l1">
        
<inertial>
            <origin rpy="0.0 0.0 0.0" xyz="-3.36876635421e-07 3.05876091067e-07 -0.0969117032233" />
            <mass value="0.0511763619538" />
            <inertia ixx="0.001" ixy="0.0" ixz="0.0" iyy="0.001" iyz="0.0" izz="0.001" />
        </inertial>

        <visual>
            <origin rpy="0.0 0.0 0.0" xyz="0.0 0.0 0.0" />
            <geometry>
                <mesh filename="package://stretch_description/meshes/link_arm_l1.STL" />
            </geometry>
            <material name="">
                <color rgba="0.792156862745 0.819607843137 0.933333333333 1.0" />
            </material>
        </visual>
        <collision>
            <origin rpy="0.0 0.0 0.0" xyz="0.0 0.0 0.0" />
            <geometry>
                <mesh filename="package://stretch_description/meshes/link_arm_l1.STL" />
            </geometry>
        </collision>
    </link>
    <joint name="joint_arm_l1" type="prismatic">
        <origin rpy="7.41596560408e-17 1.33876788297e-16 -2.44545873596e-16" xyz="0.0 0.0 0.013" />
        <axis xyz="0.0 0.0 1.0" />
        <parent link="link_arm_l2" />
        <child link="link_arm_l1" />
        <limit effort="100.0" lower="0.0" upper="0.13" velocity="1.0" />
    </joint>
    <link name="link_arm_l0">
        
<inertial>
            <origin rpy="0.0 0.0 0.0" xyz="0.0230715049668 -0.00195115833663 -0.036064634716" />
            <mass value="0.101241250325" />
            <inertia ixx="0.001" ixy="0.0" ixz="0.0" iyy="0.001" iyz="0.0" izz="0.001" />
        </inertial>

        <visual>
            <origin rpy="0.0 0.0 0.0" xyz="0.0 0.0 0.0" />
            <geometry>
                <mesh filename="package://stretch_description/meshes/link_arm_l0.STL" />
            </geometry>
            <material name="">
                <color rgba="0.792156862745 0.819607843137 0.933333333333 1.0" />
            </material>
        </visual>
        <collision>
            <origin rpy="0.0 0.0 0.0" xyz="0.0 0.0 0.0" />
            <geometry>
                <mesh filename="package://stretch_description/meshes/link_arm_l0.STL" />
            </geometry>
        </collision>
    </link>
    <joint name="joint_arm_l0" type="prismatic">
        <origin rpy="-3.05317390622e-16 -4.23236224077e-16 -2.68425135229e-17" xyz="0.0 0.0 -0.01375" />
        <axis xyz="0.0 0.0 1.0" />
        <parent link="link_arm_l1" />
        <child link="link_arm_l0" />
        <limit effort="100.0" lower="0.0" upper="0.13" velocity="1.0" />
    </joint>
    <link name="link_wrist_yaw">
        
<inertial>
            <origin rpy="0.0 0.0 0.0" xyz="-8.02795716751e-06 1.93811447768e-05 0.0189467005959" />
            <mass value="0.0405398981326" />
            <inertia ixx="0.001" ixy="0.0" ixz="0.0" iyy="0.001" iyz="0.0" izz="0.001" />
        </inertial>

        <visual>
            <origin rpy="0.0 0.0 0.0" xyz="0.0 0.0 0.0" />
            <geometry>
                <mesh filename="package://stretch_description/meshes/link_wrist_yaw.STL" />
            </geometry>
            <material name="">
                <color rgba="0.792156862745 0.819607843137 0.933333333333 1.0" />
            </material>
        </visual>
        <collision>
            <origin rpy="0.0 0.0 0.0" xyz="0.0 0.0 0.0" />
            <geometry>
                <mesh filename="package://stretch_description/meshes/link_wrist_yaw.STL" />
            </geometry>
        </collision>
    </link>
    <joint name="joint_wrist_yaw" type="revolute">
        <origin rpy="1.5708 4.2595e-14 2.6415e-15" xyz="0.083 -0.03075 0.0" />
        <axis xyz="0.0 0.0 -1.0" />
        <parent link="link_arm_l0" />
        <child link="link_wrist_yaw" />
        <limit effort="100.0" lower="-1.75" upper="4.0" velocity="1.0" />
    </joint>
    <link name="link_head">
        
<inertial>
            <origin rpy="0.0 0.0 0.0" xyz="0.0372933550589 0.0455094329856 0.0281136801213" />
            <mass value="0.129454717596" />
            <inertia ixx="0.001" ixy="0.0" ixz="0.0" iyy="0.001" iyz="0.0" izz="0.001" />
        </inertial>

        <visual>
            <origin rpy="0.0 0.0 0.0" xyz="0.0 0.0 0.0" />
            <geometry>
                <mesh filename="package://stretch_description/meshes/link_head.STL" />
            </geometry>
            <material name="">
                <color rgba="0.792156862745 0.819607843137 0.933333333333 1.0" />
            </material>
        </visual>
        <collision>
            <origin rpy="0.0 0.0 0.0" xyz="0.0 0.0 0.0" />
            <geometry>
                <mesh filename="package://stretch_description/meshes/link_head.STL" />
            </geometry>
        </collision>
    </link>
    <joint name="joint_head" type="fixed">
        <origin rpy="1.5708 -1.5615 3.1416" xyz="0.0 1.33 0.0" />
        <axis xyz="0.0 0.0 0.0" />
        <parent link="link_mast" />
        <child link="link_head" />
    </joint>
    <link name="link_head_pan">
        
<inertial>
            <origin rpy="0.0 0.0 0.0" xyz="-0.00116200255311 0.0130365621706 0.00137629842299" />
            <mass value="0.0358583411826" />
            <inertia ixx="0.001" ixy="0.0" ixz="0.0" iyy="0.001" iyz="0.0" izz="0.001" />
        </inertial>

        <visual>
            <origin rpy="0.0 0.0 0.0" xyz="0.0 0.0 0.0" />
            <geometry>
                <mesh filename="package://stretch_description/meshes/link_head_pan.STL" />
            </geometry>
            <material name="">
                <color rgba="0.792156862745 0.819607843137 0.933333333333 1.0" />
            </material>
        </visual>
        <collision>
            <origin rpy="0.0 0.0 0.0" xyz="0.0 0.0 0.0" />
            <geometry>
                <mesh filename="package://stretch_description/meshes/link_head_pan.STL" />
            </geometry>
        </collision>
    </link>
    <joint name="joint_head_pan" type="revolute">
        <origin rpy="0.00179705068142643 0.00880133802348193 1.587580660830975" xyz="0.13923956479893837 0.0720360495735024 -0.0021039677846346663" />
        <axis xyz="0.0 0.0 1.0" />
        <parent link="link_head" />
        <child link="link_head_pan" />
        <limit effort="100.0" lower="-3.9" upper="1.5" velocity="1.0" />
    </joint>
    <link name="link_head_tilt">
        
<inertial>
            <origin rpy="0.0 0.0 0.0" xyz="0.00920211049012 -0.0279724762416 0.0306580436227" />
            <mass value="0.0701242408063" />
            <inertia ixx="0.001" ixy="0.0" ixz="0.0" iyy="0.001" iyz="0.0" izz="0.001" />
        </inertial>

        <visual>
            <origin rpy="0.0 0.0 0.0" xyz="0.0 0.0 0.0" />
            <geometry>
                <mesh filename="package://stretch_description/meshes/link_head_tilt.STL" />
            </geometry>
            <material name="">
                <color rgba="0.792156862745 0.819607843137 0.933333333333 1.0" />
            </material>
        </visual>
        <collision>
            <origin rpy="0.0 0.0 0.0" xyz="0.0 0.0 0.0" />
            <geometry>
                <mesh filename="package://stretch_description/meshes/link_head_tilt.STL" />
            </geometry>
        </collision>
    </link>
    <joint name="joint_head_tilt" type="revolute">
        <origin rpy="1.604503995148521 -0.043044596422963766 -0.0012897027962114399" xyz="0.0026693953335342416 0.02891124680699318 -0.055708469623448754" />
        <axis xyz="0.0 0.0 1.0" />
        <parent link="link_head_pan" />
        <child link="link_head_tilt" />
        <limit effort="100.0" lower="-1.53" upper="0.79" velocity="1.0" />
    </joint>
    <link name="link_aruco_right_base">
        
<inertial>
            <origin rpy="0.0 0.0 0.0" xyz="0.0 0.0 -5.00000000014e-07" />
            <mass value="3.5999999999e-06" />
            <inertia ixx="0.0" ixy="0.0" ixz="0.0" iyy="0.0" iyz="0.0" izz="0.0" />
        </inertial>

        <visual>
            <origin rpy="0.0 0.0 0.0" xyz="0.0 0.0 0.0" />
            <geometry>
                <mesh filename="package://stretch_description/meshes/link_aruco_right_base.STL" />
            </geometry>
            <material name="">
                <color rgba="0.792156862745 0.819607843137 0.933333333333 1.0" />
            </material>
        </visual>
        <collision>
            <origin rpy="0.0 0.0 0.0" xyz="0.0 0.0 0.0" />
            <geometry>
                <mesh filename="package://stretch_description/meshes/link_aruco_right_base.STL" />
            </geometry>
        </collision>
    </link>
    <joint name="joint_aruco_right_base" type="fixed">
        <origin rpy="0.0 0.0 -1.57079632679" xyz="-0.005 -0.1304972 0.1597482" />
        <axis xyz="0.0 0.0 0.0" />
        <parent link="base_link" />
        <child link="link_aruco_right_base" />
    </joint>
    <link name="link_aruco_left_base">
        
<inertial>
            <origin rpy="0.0 0.0 0.0" xyz="0.0 0.0 -5.00000000014e-07" />
            <mass value="3.5999999999e-06" />
            <inertia ixx="0.0" ixy="0.0" ixz="0.0" iyy="0.0" iyz="0.0" izz="0.0" />
        </inertial>

        <visual>
            <origin rpy="0.0 0.0 0.0" xyz="0.0 0.0 0.0" />
            <geometry>
                <mesh filename="package://stretch_description/meshes/link_aruco_left_base.STL" />
            </geometry>
            <material name="">
                <color rgba="0.792156862745 0.819607843137 0.933333333333 1.0" />
            </material>
        </visual>
        <collision>
            <origin rpy="0.0 0.0 0.0" xyz="0.0 0.0 0.0" />
            <geometry>
                <mesh filename="package://stretch_description/meshes/link_aruco_left_base.STL" />
            </geometry>
        </collision>
    </link>
    <joint name="joint_aruco_left_base" type="fixed">
        <origin rpy="0.0 0.0 -1.57079632679" xyz="-0.005 0.1304972 0.1597482" />
        <axis xyz="0.0 0.0 0.0" />
        <parent link="base_link" />
        <child link="link_aruco_left_base" />
    </joint>
    <link name="link_aruco_shoulder">
        
<inertial>
            <origin rpy="0.0 0.0 0.0" xyz="-2.77555756156e-17 2.56739074445e-16 -0.000125" />
            <mass value="0.0" />
            <inertia ixx="0.0" ixy="0.0" ixz="0.0" iyy="0.0" iyz="0.0" izz="0.0" />
        </inertial>

        <visual>
            <origin rpy="0.0 0.0 0.0" xyz="0.0 0.0 0.0" />
            <geometry>
                <mesh filename="package://stretch_description/meshes/link_aruco_shoulder.STL" />
            </geometry>
            <material name="">
                <color rgba="0.792156862745 0.819607843137 0.933333333333 1.0" />
            </material>
        </visual>
        <collision>
            <origin rpy="0.0 0.0 0.0" xyz="0.0 0.0 0.0" />
            <geometry>
                <mesh filename="package://stretch_description/meshes/link_aruco_shoulder.STL" />
            </geometry>
        </collision>
    </link>
    <joint name="joint_aruco_shoulder" type="fixed">
        <origin rpy="-1.53998860118e-29 3.55962409571e-15 0.0" xyz="-0.0133768876375 0.0558540528812 0.0861368272418" />
        <axis xyz="0.0 0.0 0.0" />
        <parent link="link_lift" />
        <child link="link_aruco_shoulder" />
    </joint>
    <link name="link_aruco_top_wrist">
        
<inertial>
            <origin rpy="0.0 0.0 0.0" xyz="1.11022302463e-16 3.05311331772e-16 -0.000124999999998" />
            <mass value="0.0" />
            <inertia ixx="0.0" ixy="0.0" ixz="0.0" iyy="0.0" iyz="0.0" izz="0.0" />
        </inertial>

        <visual>
            <origin rpy="0.0 0.0 0.0" xyz="0.0 0.0 0.0" />
            <geometry>
                <mesh filename="package://stretch_description/meshes/link_aruco_top_wrist.STL" />
            </geometry>
            <material name="">
                <color rgba="0.792156862745 0.819607843137 0.933333333333 1.0" />
            </material>
        </visual>
        <collision>
            <origin rpy="0.0 0.0 0.0" xyz="0.0 0.0 0.0" />
            <geometry>
                <mesh filename="package://stretch_description/meshes/link_aruco_top_wrist.STL" />
            </geometry>
        </collision>
    </link>
    <joint name="joint_aruco_top_wrist" type="fixed">
        <origin rpy="1.57079632679 -8.03728587323e-15 3.14159265359" xyz="0.04725 0.029285 0.0" />
        <axis xyz="0.0 0.0 0.0" />
        <parent link="link_arm_l0" />
        <child link="link_aruco_top_wrist" />
    </joint>
    <link name="link_aruco_inner_wrist">
        
<inertial>
            <origin rpy="0.0 0.0 0.0" xyz="8.32667268469e-17 1.7763568394e-15 -0.000125" />
            <mass value="0.0" />
            <inertia ixx="0.0" ixy="0.0" ixz="0.0" iyy="0.0" iyz="0.0" izz="0.0" />
        </inertial>

        <visual>
            <origin rpy="0.0 0.0 0.0" xyz="0.0 0.0 0.0" />
            <geometry>
                <mesh filename="package://stretch_description/meshes/link_aruco_inner_wrist.STL" />
            </geometry>
            <material name="">
                <color rgba="0.792156862745 0.819607843137 0.933333333333 1.0" />
            </material>
        </visual>
        <collision>
            <origin rpy="0.0 0.0 0.0" xyz="0.0 0.0 0.0" />
            <geometry>
                <mesh filename="package://stretch_description/meshes/link_aruco_inner_wrist.STL" />
            </geometry>
        </collision>
    </link>
    <joint name="joint_aruco_inner_wrist" type="fixed">
        <origin rpy="3.14159265359 4.23377442363e-14 3.14159265359" xyz="0.04725 -0.0119 -0.0272499999992" />
        <axis xyz="0.0 0.0 0.0" />
        <parent link="link_arm_l0" />
        <child link="link_aruco_inner_wrist" />
    </joint>
    <material name="aluminum">
        <color rgba="0.5 0.5 0.5 1.0" />
    </material>
    <material name="plastic">
        <color rgba="0.1 0.1 0.1 1.0" />
    </material>
    <joint name="camera_joint" type="fixed">
        <origin rpy="-0.0006459980631527671 -0.035913628238259054 0.034376752349965324" xyz="0.02511070385174673 -0.012810536135353677 0.018899641409897028" />
        <parent link="link_head_tilt" />
        <child link="camera_bottom_screw_frame" />
    </joint>
    <link name="camera_bottom_screw_frame" />
    <joint name="camera_link_joint" type="fixed">
        <origin rpy="0.0 0.0 0.0" xyz="0.0106 0.0175 0.0125" />
        <parent link="camera_bottom_screw_frame" />
        <child link="camera_link" />
    </joint>
    <link name="camera_link">
        
<inertial>
            <origin rpy="0 0 0" xyz="0.0 0.0 0.0" />
            <mass value="0.072" />
            <inertia ixx="0.003881243" ixy="0.0" ixz="0.0" iyy="0.00049894" iyz="0.0" izz="0.003879257" />
        </inertial>

        <visual>
            <origin rpy="1.57079632679 0.0 1.57079632679" xyz="0.0043 -0.0175 0.0" />
            <geometry>
                <mesh filename="package://realsense2_description/meshes/d435.dae" />
            </geometry>
        </visual>
        <collision>
            <origin rpy="0.0 0.0 0.0" xyz="0.0 -0.0175 0.0" />
            <geometry>
                <box size="0.02505 0.09 0.025" />
            </geometry>
        </collision>
    </link>
    <joint name="camera_depth_joint" type="fixed">
        <origin rpy="0.0 0.0 0.0" xyz="0.0 0.0 0.0" />
        <parent link="camera_link" />
        <child link="camera_depth_frame" />
    </joint>
    <link name="camera_depth_frame" />
    <joint name="camera_depth_optical_joint" type="fixed">
        <origin rpy="-1.57079632679 0.0 -1.57079632679" xyz="0.0 0.0 0.0" />
        <parent link="camera_depth_frame" />
        <child link="camera_depth_optical_frame" />
    </joint>
    <link name="camera_depth_optical_frame" />
    <joint name="camera_infra1_joint" type="fixed">
        <origin rpy="0.0 0.0 0.0" xyz="0.0 0.0 0.0" />
        <parent link="camera_link" />
        <child link="camera_infra1_frame" />
    </joint>
    <link name="camera_infra1_frame" />
    <joint name="camera_infra1_optical_joint" type="fixed">
        <origin rpy="-1.57079632679 0.0 -1.57079632679" xyz="0.0 0.0 0.0" />
        <parent link="camera_infra1_frame" />
        <child link="camera_infra1_optical_frame" />
    </joint>
    <link name="camera_infra1_optical_frame" />
    <joint name="camera_infra2_joint" type="fixed">
        <origin rpy="0.0 0.0 0.0" xyz="0.0 -0.05 0.0" />
        <parent link="camera_link" />
        <child link="camera_infra2_frame" />
    </joint>
    <link name="camera_infra2_frame" />
    <joint name="camera_infra2_optical_joint" type="fixed">
        <origin rpy="-1.57079632679 0.0 -1.57079632679" xyz="0.0 0.0 0.0" />
        <parent link="camera_infra2_frame" />
        <child link="camera_infra2_optical_frame" />
    </joint>
    <link name="camera_infra2_optical_frame" />
    <joint name="camera_color_joint" type="fixed">
        <origin rpy="0.0 0.0 0.0" xyz="0.0 0.015 0.0" />
        <parent link="camera_link" />
        <child link="camera_color_frame" />
    </joint>
    <link name="camera_color_frame" />
    <joint name="camera_color_optical_joint" type="fixed">
        <origin rpy="-1.57079632679 0.0 -1.57079632679" xyz="0.0 0.0 0.0" />
        <parent link="camera_color_frame" />
        <child link="camera_color_optical_frame" />
    </joint>
    <link name="camera_color_optical_frame" />
    <link name="camera_accel_frame" />
    <link name="camera_accel_optical_frame" />
    <link name="camera_gyro_frame" />
    <link name="camera_gyro_optical_frame" />
    <joint name="camera_accel_joint" type="fixed">
        <origin rpy="0.0 0.0 0.0" xyz="-0.01174 -0.00552 0.0051" />
        <parent link="camera_link" />
        <child link="camera_accel_frame" />
    </joint>
    <joint name="camera_accel_optical_joint" type="fixed">
        <origin rpy="-1.57079632679 0.0 -1.57079632679" xyz="0.0 0.0 0.0" />
        <parent link="camera_accel_frame" />
        <child link="camera_accel_optical_frame" />
    </joint>
    <joint name="camera_gyro_joint" type="fixed">
        <origin rpy="0.0 0.0 0.0" xyz="-0.01174 -0.00552 0.0051" />
        <parent link="camera_link" />
        <child link="camera_gyro_frame" />
    </joint>
    <joint name="camera_gyro_optical_joint" type="fixed">
        <origin rpy="-1.57079632679 0.0 -1.57079632679" xyz="0.0 0.0 0.0" />
        <parent link="camera_gyro_frame" />
        <child link="camera_gyro_optical_frame" />
    </joint>
    <link name="laser">
        
<inertial>
            <origin rpy="0.0 0.0 0.0" xyz="0.0 0.0 -0.000755956127492" />
            <mass value="0.0749979022894" />
            <inertia ixx="0.0" ixy="0.0" ixz="0.0" iyy="0.0" iyz="0.0" izz="0.0" />
        </inertial>

        <visual>
            <origin rpy="0.0 0.0 0.0" xyz="0.0 0.0 0.0" />
            <geometry>
                <mesh filename="package://stretch_description/meshes/laser.STL" />
            </geometry>
            <material name="">
                <color rgba="0.250980392157 0.250980392157 0.250980392157 1.0" />
            </material>
        </visual>
        <collision>
            <origin rpy="0.0 0.0 0.0" xyz="0.0 0.0 0.0" />
            <geometry>
                <mesh filename="package://stretch_description/meshes/laser.STL" />
            </geometry>
        </collision>
    </link>
    <joint name="joint_laser" type="fixed">
        <origin rpy="0.0 0.0 -3.14159265359" xyz="0.000502800000001 0.0 0.1664" />
        <axis xyz="0.0 0.0 0.0" />
        <parent link="base_link" />
        <child link="laser" />
    </joint>
    <link name="respeaker_base">
        
<inertial>
            <origin rpy="0.0 0.0 0.0" xyz="-0.000780828967927 0.00765742173486 -0.00424882983019" />
            <mass value="0.00969129410417" />
            <inertia ixx="8.95656300428e-07" ixy="2.6733074581e-08" ixz="-3.84519793581e-08" iyy="4.04210996171e-07" iyz="3.15533542839e-07" izz="7.08282597118e-07" />
        </inertial>

        <visual>
            <origin rpy="0.0 0.0 0.0" xyz="0.0 0.0 0.0" />
            <geometry>
                <mesh filename="package://stretch_description/meshes/link_respeaker.STL" />
            </geometry>
            <material name="">
                <color rgba="0.792156862745 0.819607843137 0.933333333333 1.0" />
            </material>
        </visual>
        <collision>
            <origin rpy="0.0 0.0 0.0" xyz="0.0 0.0 0.0" />
            <geometry>
                <mesh filename="package://stretch_description/meshes/link_respeaker.STL" />
            </geometry>
        </collision>
    </link>
    <joint name="joint_respeaker" type="fixed">
        <origin rpy="1.5707963268 0.0 3.14159265359" xyz="1.09074743138e-05 1.36992 0.00303572796911" />
        <axis xyz="0.0 0.0 0.0" />
        <parent link="link_mast" />
        <child link="respeaker_base" />
    </joint>
    
<transmission name="trans_joint_gripper_finger_left">
        <type>transmission_interface/SimpleTransmission</type>
        <joint name="joint_gripper_finger_left">
            <hardwareInterface>hardware_interface/EffortJointInterface</hardwareInterface>
        </joint>
        <actuator name="joint_gripper_finger_left_motor">
            <hardwareInterface>hardware_interface/EffortJointInterface</hardwareInterface>
            <mechanicalReduction>1</mechanicalReduction>
        </actuator>
    </transmission>
    <transmission name="trans_joint_gripper_finger_right">
        <type>transmission_interface/SimpleTransmission</type>
        <joint name="joint_gripper_finger_right">
            <hardwareInterface>hardware_interface/EffortJointInterface</hardwareInterface>
        </joint>
        <actuator name="joint_gripper_finger_right_motor">
            <hardwareInterface>hardware_interface/EffortJointInterface</hardwareInterface>
            <mechanicalReduction>1</mechanicalReduction>
        </actuator>
    </transmission>
    <transmission name="trans_joint_right_wheel">
        <type>transmission_interface/SimpleTransmission</type>
        <joint name="joint_right_wheel">
            <hardwareInterface>hardware_interface/EffortJointInterface</hardwareInterface>
        </joint>
        <actuator name="joint_right_wheel_motor">
            <hardwareInterface>hardware_interface/EffortJointInterface</hardwareInterface>
            <mechanicalReduction>1</mechanicalReduction>
        </actuator>
    </transmission>
    <transmission name="trans_joint_left_wheel">
        <type>transmission_interface/SimpleTransmission</type>
        <joint name="joint_left_wheel">
            <hardwareInterface>hardware_interface/EffortJointInterface</hardwareInterface>
        </joint>
        <actuator name="joint_left_wheel_motor">
            <hardwareInterface>hardware_interface/EffortJointInterface</hardwareInterface>
            <mechanicalReduction>1</mechanicalReduction>
        </actuator>
    </transmission>
    <transmission name="trans_joint_lift">
        <type>transmission_interface/SimpleTransmission</type>
        <joint name="joint_lift">
            <hardwareInterface>hardware_interface/EffortJointInterface</hardwareInterface>
        </joint>
        <actuator name="joint_lift_motor">
            <hardwareInterface>hardware_interface/EffortJointInterface</hardwareInterface>
            <mechanicalReduction>1</mechanicalReduction>
        </actuator>
    </transmission>
    <transmission name="trans_joint_arm_l3">
        <type>transmission_interface/SimpleTransmission</type>
        <joint name="joint_arm_l3">
            <hardwareInterface>hardware_interface/EffortJointInterface</hardwareInterface>
        </joint>
        <actuator name="joint_arm_l3_motor">
            <hardwareInterface>hardware_interface/EffortJointInterface</hardwareInterface>
            <mechanicalReduction>1</mechanicalReduction>
        </actuator>
    </transmission>
    <transmission name="trans_joint_arm_l2">
        <type>transmission_interface/SimpleTransmission</type>
        <joint name="joint_arm_l2">
            <hardwareInterface>hardware_interface/EffortJointInterface</hardwareInterface>
        </joint>
        <actuator name="joint_arm_l2_motor">
            <hardwareInterface>hardware_interface/EffortJointInterface</hardwareInterface>
            <mechanicalReduction>1</mechanicalReduction>
        </actuator>
    </transmission>
    <transmission name="trans_joint_arm_l1">
        <type>transmission_interface/SimpleTransmission</type>
        <joint name="joint_arm_l1">
            <hardwareInterface>hardware_interface/EffortJointInterface</hardwareInterface>
        </joint>
        <actuator name="joint_arm_l1_motor">
            <hardwareInterface>hardware_interface/EffortJointInterface</hardwareInterface>
            <mechanicalReduction>1</mechanicalReduction>
        </actuator>
    </transmission>
    <transmission name="trans_joint_arm_l0">
        <type>transmission_interface/SimpleTransmission</type>
        <joint name="joint_arm_l0">
            <hardwareInterface>hardware_interface/EffortJointInterface</hardwareInterface>
        </joint>
        <actuator name="joint_arm_l0_motor">
            <hardwareInterface>hardware_interface/EffortJointInterface</hardwareInterface>
            <mechanicalReduction>1</mechanicalReduction>
        </actuator>
    </transmission>
    <transmission name="trans_joint_wrist_yaw">
        <type>transmission_interface/SimpleTransmission</type>
        <joint name="joint_wrist_yaw">
            <hardwareInterface>hardware_interface/EffortJointInterface</hardwareInterface>
        </joint>
        <actuator name="joint_wrist_yaw_motor">
            <hardwareInterface>hardware_interface/EffortJointInterface</hardwareInterface>
            <mechanicalReduction>1</mechanicalReduction>
        </actuator>
    </transmission>
    <transmission name="trans_joint_head_pan">
        <type>transmission_interface/SimpleTransmission</type>
        <joint name="joint_head_pan">
            <hardwareInterface>hardware_interface/EffortJointInterface</hardwareInterface>
        </joint>
        <actuator name="joint_head_pan_motor">
            <hardwareInterface>hardware_interface/EffortJointInterface</hardwareInterface>
            <mechanicalReduction>1</mechanicalReduction>
        </actuator>
    </transmission>
    <transmission name="trans_joint_head_tilt">
        <type>transmission_interface/SimpleTransmission</type>
        <joint name="joint_head_tilt">
            <hardwareInterface>hardware_interface/EffortJointInterface</hardwareInterface>
        </joint>
        <actuator name="joint_head_tilt_motor">
            <hardwareInterface>hardware_interface/EffortJointInterface</hardwareInterface>
            <mechanicalReduction>1</mechanicalReduction>
        </actuator>
    </transmission>
    <gazebo>
        <plugin name="gazebo_ros_control" filename="libgazebo_ros_control.so">
            <robotNamespace>/</robotNamespace>
        </plugin>
    </gazebo>
</robot>
<?xml version="1.0" ?>
<robot name="stretch_description" version="1.0">
    <link name="link_gripper">
        
<inertial>
            <origin rpy="0.0 0.0 0.0" xyz="-0.017022913273 0.0131410320934 -0.0371614759485" />
            <mass value="0.101902711393" />
            <inertia ixx="0.001" ixy="0.0" ixz="0.0" iyy="0.001" iyz="0.0" izz="0.001" />
        </inertial>

        <visual>
            <origin rpy="0.0 0.0 0.0" xyz="0.0 0.0 0.0" />
            <geometry>
                <mesh filename="package://stretch_description/meshes/link_gripper.STL" />
            </geometry>
            <material name="">
                <color rgba="0.792156862745 0.819607843137 0.933333333333 1.0" />
            </material>
        </visual>
        <collision>
            <origin rpy="0.0 0.0 0.0" xyz="0.0 0.0 0.0" />
            <geometry>
                <mesh filename="package://stretch_description/meshes/link_gripper.STL" />
            </geometry>
        </collision>
    </link>
    <joint name="joint_gripper" type="fixed">
        <origin rpy="3.14159 0.0 -1.5708" xyz="0.0 0.0 0.0" />
        <axis xyz="0.0 0.0 0.0" />
        <parent link="link_wrist_yaw" />
        <child link="link_gripper" />
    </joint>
    <link name="link_gripper_finger_left">
        
<inertial>
            <origin rpy="0.0 0.0 0.0" xyz="0.094504748351 0.0124301080924 -4.4408920985e-16" />
            <mass value="0.0476207785199" />
            <inertia ixx="0.001" ixy="0.0" ixz="0.0" iyy="0.001" iyz="0.0" izz="0.001" />
        </inertial>

        <visual>
            <origin rpy="0.0 0.0 0.0" xyz="0.0 0.0 0.0" />
            <geometry>
                <mesh filename="package://stretch_description/meshes/link_gripper_finger_left.STL" scale="0.9 1.0 1.0" />
            </geometry>
            <material name="">
                <color rgba="0.792156862745 0.819607843137 0.933333333333 1.0" />
            </material>
        </visual>
        <collision>
            <origin rpy="0.0 0.0 0.0" xyz="0.0 0.0 0.0" />
            <geometry>
                <mesh filename="package://stretch_description/meshes/link_gripper_finger_left.STL" scale="0.9 1.0 1.0" />
            </geometry>
        </collision>
    </link>
    <joint name="joint_gripper_finger_left" type="revolute">
        <origin rpy="2.1762e-15 0.5236 3.1416" xyz="-0.047231 -0.010151 -0.04679" />
        <axis xyz="0.0 0.0 1.0" />
        <parent link="link_gripper" />
        <child link="link_gripper_finger_left" />
        <limit effort="100.0" lower="-0.6" upper="0.6" velocity="1.0" />
    </joint>
    <link name="link_gripper_fingertip_left">
        
<inertial>
            <origin rpy="0.0 0.0 0.0" xyz="-3.16381381649e-08 -2.91408530639e-09 0.00812579670382" />
            <mass value="0.00382159917456" />
            <inertia ixx="0.001" ixy="0.0" ixz="0.0" iyy="0.001" iyz="0.0" izz="0.001" />
        </inertial>

        <visual>
            <origin rpy="0.0 0.0 0.0" xyz="0.0 0.0 0.0" />
            <geometry>
                <mesh filename="package://stretch_description/meshes/link_gripper_fingertip_left.STL" />
            </geometry>
            <material name="">
                <color rgba="0.250980392157 0.250980392157 0.250980392157 1.0" />
            </material>
        </visual>
        <collision>
            <origin rpy="0.0 0.0 0.0" xyz="0.0 0.0 0.0" />
            <geometry>
                <mesh filename="package://stretch_description/meshes/link_gripper_fingertip_left.STL" />
            </geometry>
        </collision>
    </link>
    <joint name="joint_gripper_fingertip_left" type="fixed">
        <origin rpy="-1.5708 -4.774e-15 -2.5545" xyz="0.171099 0.014912 0.0" />
        <axis xyz="0.0 0.0 0.0" />
        <parent link="link_gripper_finger_left" />
        <child link="link_gripper_fingertip_left" />
    </joint>
    <link name="link_gripper_finger_right">
        
<inertial>
            <origin rpy="0.0 0.0 0.0" xyz="-0.094504748351 -0.0124301080924 0.0" />
            <mass value="0.0476207785199" />
            <inertia ixx="0.001" ixy="0.0" ixz="0.0" iyy="0.001" iyz="0.0" izz="0.001" />
        </inertial>

        <visual>
            <origin rpy="0.0 0.0 0.0" xyz="0.0 0.0 0.0" />
            <geometry>
                <mesh filename="package://stretch_description/meshes/link_gripper_finger_right.STL" scale="0.9 1.0 1.0" />
            </geometry>
            <material name="">
                <color rgba="0.792156862745 0.819607843137 0.933333333333 1.0" />
            </material>
        </visual>
        <collision>
            <origin rpy="0.0 0.0 0.0" xyz="0.0 0.0 0.0" />
            <geometry>
                <mesh filename="package://stretch_description/meshes/link_gripper_finger_right.STL" scale="0.9 1.0 1.0" />
            </geometry>
        </collision>
    </link>
    <joint name="joint_gripper_finger_right" type="revolute">
        <origin rpy="3.1416 -0.5236 1.2943e-15" xyz="-0.047231 0.010049 -0.04679" />
        <axis xyz="0.0 0.0 1.0" />
        <parent link="link_gripper" />
        <child link="link_gripper_finger_right" />
        <limit effort="100.0" lower="-0.6" upper="0.6" velocity="1.0" />
    </joint>
    <link name="link_gripper_fingertip_right">
        
<inertial>
            <origin rpy="0.0 0.0 0.0" xyz="2.59386303963e-08 6.70949018566e-09 0.0081257951613" />
            <mass value="0.0038216003732" />
            <inertia ixx="0.001" ixy="0.0" ixz="0.0" iyy="0.001" iyz="0.0" izz="0.001" />
        </inertial>

        <visual>
            <origin rpy="0.0 0.0 0.0" xyz="0.0 0.0 0.0" />
            <geometry>
                <mesh filename="package://stretch_description/meshes/link_gripper_fingertip_right.STL" />
            </geometry>
            <material name="">
                <color rgba="0.250980392157 0.250980392157 0.250980392157 1.0" />
            </material>
        </visual>
        <collision>
            <origin rpy="0.0 0.0 0.0" xyz="0.0 0.0 0.0" />
            <geometry>
                <mesh filename="package://stretch_description/meshes/link_gripper_fingertip_right.STL" />
            </geometry>
        </collision>
    </link>
    <joint name="joint_gripper_fingertip_right" type="fixed">
        <origin rpy="-1.5708 -2.0539e-15 0.58705" xyz="-0.171099 -0.014912 0.0" />
        <axis xyz="0.0 0.0 0.0" />
        <parent link="link_gripper_finger_right" />
        <child link="link_gripper_fingertip_right" />
    </joint>
    <link name="link_grasp_center" />
    <joint name="joint_grasp_center" type="fixed">
        <origin rpy="0.0 0.0 3.141579" xyz="-0.205478 0.0 -0.138154" />
        <parent link="link_gripper" />
        <child link="link_grasp_center" />
    </joint>
    <link name="base_link">
        
<inertial>
            <origin rpy="0.0 0.0 0.0" xyz="-0.109461304328 -0.000741018909048 0.091491526943" />
            <mass value="1.07237826598" />
            <inertia ixx="0.0031058090771" ixy="1.51828481911e-06" ixz="0.000416904667324" iyy="0.00433798719992" iyz="1.33487716258e-05" izz="0.00372047274674" />
        </inertial>

        <visual>
            <origin rpy="0.0 0.0 0.0" xyz="0.0 0.0 0.0" />
            <geometry>
                <mesh filename="package://stretch_description/meshes/base_link.STL" />
            </geometry>
            <material name="">
                <color rgba="0.792156862745 0.819607843137 0.933333333333 1.0" />
            </material>
        </visual>
        <collision>
            <origin rpy="0.0 0.0 0.0" xyz="0.0 0.0 0.0" />
            <geometry>
                <mesh filename="package://stretch_description/meshes/base_link.STL" />
            </geometry>
        </collision>
    </link>
    <link name="link_right_wheel">
        
<inertial>
            <origin rpy="0.0 0.0 0.0" xyz="1.25554620867e-07 3.54748938447e-07 0.0239581106165" />
            <mass value="0.01" />
            <inertia ixx="0.001" ixy="0.0" ixz="0.0" iyy="0.001" iyz="0.0" izz="0.001" />
        </inertial>

        <visual>
            <origin rpy="0.0 0.0 0.0" xyz="0.0 0.0 0.0" />
            <geometry>
                <mesh filename="package://stretch_description/meshes/link_right_wheel.STL" />
            </geometry>
            <material name="">
                <color rgba="0.792156862745 0.819607843137 0.933333333333 1.0" />
            </material>
        </visual>
        <collision>
            <origin rpy="0.0 0.0 0.0" xyz="0.0 0.0 0.0" />
            <geometry>
                <mesh filename="package://stretch_description/meshes/link_right_wheel.STL" />
            </geometry>
        </collision>
    </link>
    <joint name="joint_right_wheel" type="continuous">
        <origin rpy="-1.57079632679 -1.11022302463e-16 7.2858385991e-17" xyz="-0.003 -0.15765 0.0508" />
        <axis xyz="0.0 0.0 1.0" />
        <parent link="base_link" />
        <child link="link_right_wheel" />
        <dynamics damping="21.75" friction="10.48" />
    </joint>
    <link name="link_left_wheel">
        
<inertial>
            <origin rpy="0.0 0.0 0.0" xyz="1.25554620922e-07 -3.54748938503e-07 -0.0239581106165" />
            <mass value="0.01" />
            <inertia ixx="0.001" ixy="0.0" ixz="0.0" iyy="0.001" iyz="0.0" izz="0.001" />
        </inertial>

        <visual>
            <origin rpy="0.0 0.0 0.0" xyz="0.0 0.0 0.0" />
            <geometry>
                <mesh filename="package://stretch_description/meshes/link_left_wheel.STL" />
            </geometry>
            <material name="">
                <color rgba="0.792156862745 0.819607843137 0.933333333333 1.0" />
            </material>
        </visual>
        <collision>
            <origin rpy="0.0 0.0 0.0" xyz="0.0 0.0 0.0" />
            <geometry>
                <mesh filename="package://stretch_description/meshes/link_left_wheel.STL" />
            </geometry>
        </collision>
    </link>
    <joint name="joint_left_wheel" type="continuous">
        <origin rpy="-1.57079632679 3.16227047921e-31 7.88745438254e-16" xyz="-0.00300000000002 0.15765 0.0508" />
        <axis xyz="0.0 0.0 1.0" />
        <parent link="base_link" />
        <child link="link_left_wheel" />
        <dynamics damping="21.75" friction="10.48" />
    </joint>
    <link name="caster_link">
        
<inertial>
            <origin rpy="0 0 0" xyz="0.0 0.0 0.0" />
            <mass value="0.01" />
            <inertia ixx="0.001" ixy="0.0" ixz="0.0" iyy="0.001" iyz="0.0" izz="0.001" />
        </inertial>

        <collision>
            <origin rpy="0.0 0.0 0.0" xyz="0.0 0.0 0.0" />
            <geometry>
                <sphere radius="0.032" />
            </geometry>
        </collision>
        <visual>
            <origin rpy="0.0 0.0 0.0" xyz="0.0 0.0 0.0" />
            <geometry>
                <mesh filename="package://stretch_description/meshes/omni_wheel_m.STL" />
            </geometry>
            <material name="">
                <color rgba="0.792156862745 0.819607843137 0.933333333333 1.0" />
            </material>
        </visual>
    </link>
    <joint name="caster_joint" type="fixed">
        <origin rpy="-1.57079632679 0.0 0.0" xyz="-0.245 0.0 0.032" />
        <axis xyz="0.0 0.0 1.0" />
        <parent link="base_link" />
        <child link="caster_link" />
    </joint>
    <link name="link_mast">
        
<inertial>
            <origin rpy="0.0 0.0 0.0" xyz="0.00755818572976 0.773971284177 0.0064731308662" />
            <mass value="0.749143203376" />
            <inertia ixx="0.0709854511955" ixy="-0.00433428742758" ixz="-0.000186110788698" iyy="0.000437922053343" iyz="-0.00288788257713" izz="0.0711048085017" />
        </inertial>

        <visual>
            <origin rpy="0.0 0.0 0.0" xyz="0.0 0.0 0.0" />
            <geometry>
                <mesh filename="package://stretch_description/meshes/link_mast.STL" />
            </geometry>
            <material name="">
                <color rgba="0.792156862745 0.819607843137 0.933333333333 1.0" />
            </material>
        </visual>
        <collision>
            <origin rpy="0.0 0.0 0.0" xyz="0.0 0.0 0.0" />
            <geometry>
                <mesh filename="package://stretch_description/meshes/link_mast.STL" />
            </geometry>
        </collision>
    </link>
    <joint name="joint_mast" type="fixed">
        <origin rpy="1.5590397612212408 0.023427641144290412 0.006739448561568549" xyz="-0.07387773964359509 0.13783243762213837 0.03235333347342398" />
        <axis xyz="0.0 0.0 0.0" />
        <parent link="base_link" />
        <child link="link_mast" />
    </joint>
    <link name="link_lift">
        
<inertial>
            <origin rpy="0.0 0.0 0.0" xyz="-0.0547636346253 0.0380939689802 0.00933159404448" />
            <mass value="0.444820831236" />
            <inertia ixx="0.000567192946271" ixy="-0.000246075347895" ixz="-0.000128108442261" iyy="0.00127108364479" iyz="7.6191685507e-06" izz="0.00137296635099" />
        </inertial>

        <visual>
            <origin rpy="0.0 0.0 0.0" xyz="0.0 0.0 0.0" />
            <geometry>
                <mesh filename="package://stretch_description/meshes/link_lift.STL" />
            </geometry>
            <material name="">
                <color rgba="0.792156862745 0.819607843137 0.933333333333 1.0" />
            </material>
        </visual>
        <collision>
            <origin rpy="0.0 0.0 0.0" xyz="0.0 0.0 0.0" />
            <geometry>
                <mesh filename="package://stretch_description/meshes/link_lift.STL" />
            </geometry>
        </collision>
    </link>
    <joint name="joint_lift" type="prismatic">
        <origin rpy="-1.5707963268 1.56154313753 -6.29420043665e-13" xyz="-0.0369217062323 0.1654712 -0.000341653286794" />
        <axis xyz="0.0 0.0 1.0" />
        <parent link="link_mast" />
        <child link="link_lift" />
        <limit effort="100.0" lower="0.0" upper="1.1" velocity="1.0" />
    </joint>
    <link name="link_arm_l4">
        
<inertial>
            <origin rpy="0.0 0.0 0.0" xyz="-1.61247276464e-06 1.54715589201e-06 -0.095325270604" />
            <mass value="0.067652545579" />
            <inertia ixx="0.000122002023067" ixy="7.2959335623e-13" ixz="9.63170353371e-09" iyy="0.000122002023127" iyz="-9.24154949889e-09" izz="1.4604343981e-12" />
        </inertial>

        <visual>
            <origin rpy="0.0 0.0 0.0" xyz="0.0 0.0 0.0" />
            <geometry>
                <mesh filename="package://stretch_description/meshes/link_arm_l4.STL" />
            </geometry>
            <material name="">
                <color rgba="0.792156862745 0.819607843137 0.933333333333 1.0" />
            </material>
        </visual>
        <collision>
            <origin rpy="0.0 0.0 0.0" xyz="0.0 0.0 0.0" />
            <geometry>
                <mesh filename="package://stretch_description/meshes/link_arm_l4.STL" />
            </geometry>
        </collision>
    </link>
    <joint name="joint_arm_l4" type="fixed">
        <origin rpy="1.5706370742481743 -0.04861394029305366 -1.5999203239650384" xyz="-0.26004302676731866 -0.005686684848839391 -0.004811536075100588" />
        <axis xyz="0.0 0.0 0.0" />
        <parent link="link_lift" />
        <child link="link_arm_l4" />
    </joint>
    <link name="link_arm_l3">
        
<inertial>
            <origin rpy="0.0 0.0 0.0" xyz="-3.34873468621e-07 4.74113363069e-07 -0.0974069598289" />
            <mass value="0.0626921047058" />
            <inertia ixx="0.001" ixy="0.0" ixz="0.0" iyy="0.001" iyz="0.0" izz="0.001" />
        </inertial>

        <visual>
            <origin rpy="0.0 0.0 0.0" xyz="0.0 0.0 0.0" />
            <geometry>
                <mesh filename="package://stretch_description/meshes/link_arm_l3.STL" />
            </geometry>
            <material name="">
                <color rgba="0.792156862745 0.819607843137 0.933333333333 1.0" />
            </material>
        </visual>
        <collision>
            <origin rpy="0.0 0.0 0.0" xyz="0.0 0.0 0.0" />
            <geometry>
                <mesh filename="package://stretch_description/meshes/link_arm_l3.STL" />
            </geometry>
        </collision>
    </link>
    <joint name="joint_arm_l3" type="prismatic">
        <origin rpy="3.5742e-16 3.2123e-16 -2.4565e-16" xyz="0.0 0.0 0.013" />
        <axis xyz="0.0 0.0 1.0" />
        <parent link="link_arm_l4" />
        <child link="link_arm_l3" />
        <limit effort="100.0" lower="0.0" upper="0.13" velocity="1.0" />
    </joint>
    <link name="link_arm_l2">
        
<inertial>
            <origin rpy="0.0 0.0 0.0" xyz="-3.31043560509e-07 3.13422303999e-07 -0.0972558835419" />
            <mass value="0.0569074368576" />
            <inertia ixx="0.001" ixy="0.0" ixz="0.0" iyy="0.001" iyz="0.0" izz="0.001" />
        </inertial>

        <visual>
            <origin rpy="0.0 0.0 0.0" xyz="0.0 0.0 0.0" />
            <geometry>
                <mesh filename="package://stretch_description/meshes/link_arm_l2.STL" />
            </geometry>
            <material name="">
                <color rgba="0.792156862745 0.819607843137 0.933333333333 1.0" />
            </material>
        </visual>
        <collision>
            <origin rpy="0.0 0.0 0.0" xyz="0.0 0.0 0.0" />
            <geometry>
                <mesh filename="package://stretch_description/meshes/link_arm_l2.STL" />
            </geometry>
        </collision>
    </link>
    <joint name="joint_arm_l2" type="prismatic">
        <origin rpy="2.91385731014e-16 4.44300759505e-17 3.25691080516e-16" xyz="0.0 0.0 0.013" />
        <axis xyz="0.0 0.0 1.0" />
        <parent link="link_arm_l3" />
        <child link="link_arm_l2" />
        <limit effort="100.0" lower="0.0" upper="0.13" velocity="1.0" />
    </joint>
    <link name="link_arm_l1">
        
<inertial>
            <origin rpy="0.0 0.0 0.0" xyz="-3.36876635421e-07 3.05876091067e-07 -0.0969117032233" />
            <mass value="0.0511763619538" />
            <inertia ixx="0.001" ixy="0.0" ixz="0.0" iyy="0.001" iyz="0.0" izz="0.001" />
        </inertial>

        <visual>
            <origin rpy="0.0 0.0 0.0" xyz="0.0 0.0 0.0" />
            <geometry>
                <mesh filename="package://stretch_description/meshes/link_arm_l1.STL" />
            </geometry>
            <material name="">
                <color rgba="0.792156862745 0.819607843137 0.933333333333 1.0" />
            </material>
        </visual>
        <collision>
            <origin rpy="0.0 0.0 0.0" xyz="0.0 0.0 0.0" />
            <geometry>
                <mesh filename="package://stretch_description/meshes/link_arm_l1.STL" />
            </geometry>
        </collision>
    </link>
    <joint name="joint_arm_l1" type="prismatic">
        <origin rpy="7.41596560408e-17 1.33876788297e-16 -2.44545873596e-16" xyz="0.0 0.0 0.013" />
        <axis xyz="0.0 0.0 1.0" />
        <parent link="link_arm_l2" />
        <child link="link_arm_l1" />
        <limit effort="100.0" lower="0.0" upper="0.13" velocity="1.0" />
    </joint>
    <link name="link_arm_l0">
        
<inertial>
            <origin rpy="0.0 0.0 0.0" xyz="0.0230715049668 -0.00195115833663 -0.036064634716" />
            <mass value="0.101241250325" />
            <inertia ixx="0.001" ixy="0.0" ixz="0.0" iyy="0.001" iyz="0.0" izz="0.001" />
        </inertial>

        <visual>
            <origin rpy="0.0 0.0 0.0" xyz="0.0 0.0 0.0" />
            <geometry>
                <mesh filename="package://stretch_description/meshes/link_arm_l0.STL" />
            </geometry>
            <material name="">
                <color rgba="0.792156862745 0.819607843137 0.933333333333 1.0" />
            </material>
        </visual>
        <collision>
            <origin rpy="0.0 0.0 0.0" xyz="0.0 0.0 0.0" />
            <geometry>
                <mesh filename="package://stretch_description/meshes/link_arm_l0.STL" />
            </geometry>
        </collision>
    </link>
    <joint name="joint_arm_l0" type="prismatic">
        <origin rpy="-3.05317390622e-16 -4.23236224077e-16 -2.68425135229e-17" xyz="0.0 0.0 -0.01375" />
        <axis xyz="0.0 0.0 1.0" />
        <parent link="link_arm_l1" />
        <child link="link_arm_l0" />
        <limit effort="100.0" lower="0.0" upper="0.13" velocity="1.0" />
    </joint>
    <link name="link_wrist_yaw">
        
<inertial>
            <origin rpy="0.0 0.0 0.0" xyz="-8.02795716751e-06 1.93811447768e-05 0.0189467005959" />
            <mass value="0.0405398981326" />
            <inertia ixx="0.001" ixy="0.0" ixz="0.0" iyy="0.001" iyz="0.0" izz="0.001" />
        </inertial>

        <visual>
            <origin rpy="0.0 0.0 0.0" xyz="0.0 0.0 0.0" />
            <geometry>
                <mesh filename="package://stretch_description/meshes/link_wrist_yaw.STL" />
            </geometry>
            <material name="">
                <color rgba="0.792156862745 0.819607843137 0.933333333333 1.0" />
            </material>
        </visual>
        <collision>
            <origin rpy="0.0 0.0 0.0" xyz="0.0 0.0 0.0" />
            <geometry>
                <mesh filename="package://stretch_description/meshes/link_wrist_yaw.STL" />
            </geometry>
        </collision>
    </link>
    <joint name="joint_wrist_yaw" type="revolute">
        <origin rpy="1.5708 4.2595e-14 2.6415e-15" xyz="0.083 -0.03075 0.0" />
        <axis xyz="0.0 0.0 -1.0" />
        <parent link="link_arm_l0" />
        <child link="link_wrist_yaw" />
        <limit effort="100.0" lower="-1.75" upper="4.0" velocity="1.0" />
    </joint>
    <link name="link_head">
        
<inertial>
            <origin rpy="0.0 0.0 0.0" xyz="0.0372933550589 0.0455094329856 0.0281136801213" />
            <mass value="0.129454717596" />
            <inertia ixx="0.001" ixy="0.0" ixz="0.0" iyy="0.001" iyz="0.0" izz="0.001" />
        </inertial>

        <visual>
            <origin rpy="0.0 0.0 0.0" xyz="0.0 0.0 0.0" />
            <geometry>
                <mesh filename="package://stretch_description/meshes/link_head.STL" />
            </geometry>
            <material name="">
                <color rgba="0.792156862745 0.819607843137 0.933333333333 1.0" />
            </material>
        </visual>
        <collision>
            <origin rpy="0.0 0.0 0.0" xyz="0.0 0.0 0.0" />
            <geometry>
                <mesh filename="package://stretch_description/meshes/link_head.STL" />
            </geometry>
        </collision>
    </link>
    <joint name="joint_head" type="fixed">
        <origin rpy="1.5708 -1.5615 3.1416" xyz="0.0 1.33 0.0" />
        <axis xyz="0.0 0.0 0.0" />
        <parent link="link_mast" />
        <child link="link_head" />
    </joint>
    <link name="link_head_pan">
        
<inertial>
            <origin rpy="0.0 0.0 0.0" xyz="-0.00116200255311 0.0130365621706 0.00137629842299" />
            <mass value="0.0358583411826" />
            <inertia ixx="0.001" ixy="0.0" ixz="0.0" iyy="0.001" iyz="0.0" izz="0.001" />
        </inertial>

        <visual>
            <origin rpy="0.0 0.0 0.0" xyz="0.0 0.0 0.0" />
            <geometry>
                <mesh filename="package://stretch_description/meshes/link_head_pan.STL" />
            </geometry>
            <material name="">
                <color rgba="0.792156862745 0.819607843137 0.933333333333 1.0" />
            </material>
        </visual>
        <collision>
            <origin rpy="0.0 0.0 0.0" xyz="0.0 0.0 0.0" />
            <geometry>
                <mesh filename="package://stretch_description/meshes/link_head_pan.STL" />
            </geometry>
        </collision>
    </link>
    <joint name="joint_head_pan" type="revolute">
        <origin rpy="0.00179705068142643 0.00880133802348193 1.587580660830975" xyz="0.13923956479893837 0.0720360495735024 -0.0021039677846346663" />
        <axis xyz="0.0 0.0 1.0" />
        <parent link="link_head" />
        <child link="link_head_pan" />
        <limit effort="100.0" lower="-3.9" upper="1.5" velocity="1.0" />
    </joint>
    <link name="link_head_tilt">
        
<inertial>
            <origin rpy="0.0 0.0 0.0" xyz="0.00920211049012 -0.0279724762416 0.0306580436227" />
            <mass value="0.0701242408063" />
            <inertia ixx="0.001" ixy="0.0" ixz="0.0" iyy="0.001" iyz="0.0" izz="0.001" />
        </inertial>

        <visual>
            <origin rpy="0.0 0.0 0.0" xyz="0.0 0.0 0.0" />
            <geometry>
                <mesh filename="package://stretch_description/meshes/link_head_tilt.STL" />
            </geometry>
            <material name="">
                <color rgba="0.792156862745 0.819607843137 0.933333333333 1.0" />
            </material>
        </visual>
        <collision>
            <origin rpy="0.0 0.0 0.0" xyz="0.0 0.0 0.0" />
            <geometry>
                <mesh filename="package://stretch_description/meshes/link_head_tilt.STL" />
            </geometry>
        </collision>
    </link>
    <joint name="joint_head_tilt" type="revolute">
        <origin rpy="1.604503995148521 -0.043044596422963766 -0.0012897027962114399" xyz="0.0026693953335342416 0.02891124680699318 -0.055708469623448754" />
        <axis xyz="0.0 0.0 1.0" />
        <parent link="link_head_pan" />
        <child link="link_head_tilt" />
        <limit effort="100.0" lower="-1.53" upper="0.79" velocity="1.0" />
    </joint>
    <link name="link_aruco_right_base">
        
<inertial>
            <origin rpy="0.0 0.0 0.0" xyz="0.0 0.0 -5.00000000014e-07" />
            <mass value="3.5999999999e-06" />
            <inertia ixx="0.0" ixy="0.0" ixz="0.0" iyy="0.0" iyz="0.0" izz="0.0" />
        </inertial>

        <visual>
            <origin rpy="0.0 0.0 0.0" xyz="0.0 0.0 0.0" />
            <geometry>
                <mesh filename="package://stretch_description/meshes/link_aruco_right_base.STL" />
            </geometry>
            <material name="">
                <color rgba="0.792156862745 0.819607843137 0.933333333333 1.0" />
            </material>
        </visual>
        <collision>
            <origin rpy="0.0 0.0 0.0" xyz="0.0 0.0 0.0" />
            <geometry>
                <mesh filename="package://stretch_description/meshes/link_aruco_right_base.STL" />
            </geometry>
        </collision>
    </link>
    <joint name="joint_aruco_right_base" type="fixed">
        <origin rpy="0.0 0.0 -1.57079632679" xyz="-0.005 -0.1304972 0.1597482" />
        <axis xyz="0.0 0.0 0.0" />
        <parent link="base_link" />
        <child link="link_aruco_right_base" />
    </joint>
    <link name="link_aruco_left_base">
        
<inertial>
            <origin rpy="0.0 0.0 0.0" xyz="0.0 0.0 -5.00000000014e-07" />
            <mass value="3.5999999999e-06" />
            <inertia ixx="0.0" ixy="0.0" ixz="0.0" iyy="0.0" iyz="0.0" izz="0.0" />
        </inertial>

        <visual>
            <origin rpy="0.0 0.0 0.0" xyz="0.0 0.0 0.0" />
            <geometry>
                <mesh filename="package://stretch_description/meshes/link_aruco_left_base.STL" />
            </geometry>
            <material name="">
                <color rgba="0.792156862745 0.819607843137 0.933333333333 1.0" />
            </material>
        </visual>
        <collision>
            <origin rpy="0.0 0.0 0.0" xyz="0.0 0.0 0.0" />
            <geometry>
                <mesh filename="package://stretch_description/meshes/link_aruco_left_base.STL" />
            </geometry>
        </collision>
    </link>
    <joint name="joint_aruco_left_base" type="fixed">
        <origin rpy="0.0 0.0 -1.57079632679" xyz="-0.005 0.1304972 0.1597482" />
        <axis xyz="0.0 0.0 0.0" />
        <parent link="base_link" />
        <child link="link_aruco_left_base" />
    </joint>
    <link name="link_aruco_shoulder">
        
<inertial>
            <origin rpy="0.0 0.0 0.0" xyz="-2.77555756156e-17 2.56739074445e-16 -0.000125" />
            <mass value="0.0" />
            <inertia ixx="0.0" ixy="0.0" ixz="0.0" iyy="0.0" iyz="0.0" izz="0.0" />
        </inertial>

        <visual>
            <origin rpy="0.0 0.0 0.0" xyz="0.0 0.0 0.0" />
            <geometry>
                <mesh filename="package://stretch_description/meshes/link_aruco_shoulder.STL" />
            </geometry>
            <material name="">
                <color rgba="0.792156862745 0.819607843137 0.933333333333 1.0" />
            </material>
        </visual>
        <collision>
            <origin rpy="0.0 0.0 0.0" xyz="0.0 0.0 0.0" />
            <geometry>
                <mesh filename="package://stretch_description/meshes/link_aruco_shoulder.STL" />
            </geometry>
        </collision>
    </link>
    <joint name="joint_aruco_shoulder" type="fixed">
        <origin rpy="-1.53998860118e-29 3.55962409571e-15 0.0" xyz="-0.0133768876375 0.0558540528812 0.0861368272418" />
        <axis xyz="0.0 0.0 0.0" />
        <parent link="link_lift" />
        <child link="link_aruco_shoulder" />
    </joint>
    <link name="link_aruco_top_wrist">
        
<inertial>
            <origin rpy="0.0 0.0 0.0" xyz="1.11022302463e-16 3.05311331772e-16 -0.000124999999998" />
            <mass value="0.0" />
            <inertia ixx="0.0" ixy="0.0" ixz="0.0" iyy="0.0" iyz="0.0" izz="0.0" />
        </inertial>

        <visual>
            <origin rpy="0.0 0.0 0.0" xyz="0.0 0.0 0.0" />
            <geometry>
                <mesh filename="package://stretch_description/meshes/link_aruco_top_wrist.STL" />
            </geometry>
            <material name="">
                <color rgba="0.792156862745 0.819607843137 0.933333333333 1.0" />
            </material>
        </visual>
        <collision>
            <origin rpy="0.0 0.0 0.0" xyz="0.0 0.0 0.0" />
            <geometry>
                <mesh filename="package://stretch_description/meshes/link_aruco_top_wrist.STL" />
            </geometry>
        </collision>
    </link>
    <joint name="joint_aruco_top_wrist" type="fixed">
        <origin rpy="1.57079632679 -8.03728587323e-15 3.14159265359" xyz="0.04725 0.029285 0.0" />
        <axis xyz="0.0 0.0 0.0" />
        <parent link="link_arm_l0" />
        <child link="link_aruco_top_wrist" />
    </joint>
    <link name="link_aruco_inner_wrist">
        
<inertial>
            <origin rpy="0.0 0.0 0.0" xyz="8.32667268469e-17 1.7763568394e-15 -0.000125" />
            <mass value="0.0" />
            <inertia ixx="0.0" ixy="0.0" ixz="0.0" iyy="0.0" iyz="0.0" izz="0.0" />
        </inertial>

        <visual>
            <origin rpy="0.0 0.0 0.0" xyz="0.0 0.0 0.0" />
            <geometry>
                <mesh filename="package://stretch_description/meshes/link_aruco_inner_wrist.STL" />
            </geometry>
            <material name="">
                <color rgba="0.792156862745 0.819607843137 0.933333333333 1.0" />
            </material>
        </visual>
        <collision>
            <origin rpy="0.0 0.0 0.0" xyz="0.0 0.0 0.0" />
            <geometry>
                <mesh filename="package://stretch_description/meshes/link_aruco_inner_wrist.STL" />
            </geometry>
        </collision>
    </link>
    <joint name="joint_aruco_inner_wrist" type="fixed">
        <origin rpy="3.14159265359 4.23377442363e-14 3.14159265359" xyz="0.04725 -0.0119 -0.0272499999992" />
        <axis xyz="0.0 0.0 0.0" />
        <parent link="link_arm_l0" />
        <child link="link_aruco_inner_wrist" />
    </joint>
    <material name="aluminum">
        <color rgba="0.5 0.5 0.5 1.0" />
    </material>
    <material name="plastic">
        <color rgba="0.1 0.1 0.1 1.0" />
    </material>
    <joint name="camera_joint" type="fixed">
        <origin rpy="-0.0006459980631527671 -0.035913628238259054 0.034376752349965324" xyz="0.02511070385174673 -0.012810536135353677 0.018899641409897028" />
        <parent link="link_head_tilt" />
        <child link="camera_bottom_screw_frame" />
    </joint>
    <link name="camera_bottom_screw_frame" />
    <joint name="camera_link_joint" type="fixed">
        <origin rpy="0.0 0.0 0.0" xyz="0.0106 0.0175 0.0125" />
        <parent link="camera_bottom_screw_frame" />
        <child link="camera_link" />
    </joint>
    <link name="camera_link">
        
<inertial>
            <origin rpy="0 0 0" xyz="0.0 0.0 0.0" />
            <mass value="0.072" />
            <inertia ixx="0.003881243" ixy="0.0" ixz="0.0" iyy="0.00049894" iyz="0.0" izz="0.003879257" />
        </inertial>

        <visual>
            <origin rpy="1.57079632679 0.0 1.57079632679" xyz="0.0043 -0.0175 0.0" />
            <geometry>
                <mesh filename="package://realsense2_description/meshes/d435.dae" />
            </geometry>
        </visual>
        <collision>
            <origin rpy="0.0 0.0 0.0" xyz="0.0 -0.0175 0.0" />
            <geometry>
                <box size="0.02505 0.09 0.025" />
            </geometry>
        </collision>
    </link>
    <joint name="camera_depth_joint" type="fixed">
        <origin rpy="0.0 0.0 0.0" xyz="0.0 0.0 0.0" />
        <parent link="camera_link" />
        <child link="camera_depth_frame" />
    </joint>
    <link name="camera_depth_frame" />
    <joint name="camera_depth_optical_joint" type="fixed">
        <origin rpy="-1.57079632679 0.0 -1.57079632679" xyz="0.0 0.0 0.0" />
        <parent link="camera_depth_frame" />
        <child link="camera_depth_optical_frame" />
    </joint>
    <link name="camera_depth_optical_frame" />
    <joint name="camera_infra1_joint" type="fixed">
        <origin rpy="0.0 0.0 0.0" xyz="0.0 0.0 0.0" />
        <parent link="camera_link" />
        <child link="camera_infra1_frame" />
    </joint>
    <link name="camera_infra1_frame" />
    <joint name="camera_infra1_optical_joint" type="fixed">
        <origin rpy="-1.57079632679 0.0 -1.57079632679" xyz="0.0 0.0 0.0" />
        <parent link="camera_infra1_frame" />
        <child link="camera_infra1_optical_frame" />
    </joint>
    <link name="camera_infra1_optical_frame" />
    <joint name="camera_infra2_joint" type="fixed">
        <origin rpy="0.0 0.0 0.0" xyz="0.0 -0.05 0.0" />
        <parent link="camera_link" />
        <child link="camera_infra2_frame" />
    </joint>
    <link name="camera_infra2_frame" />
    <joint name="camera_infra2_optical_joint" type="fixed">
        <origin rpy="-1.57079632679 0.0 -1.57079632679" xyz="0.0 0.0 0.0" />
        <parent link="camera_infra2_frame" />
        <child link="camera_infra2_optical_frame" />
    </joint>
    <link name="camera_infra2_optical_frame" />
    <joint name="camera_color_joint" type="fixed">
        <origin rpy="0.0 0.0 0.0" xyz="0.0 0.015 0.0" />
        <parent link="camera_link" />
        <child link="camera_color_frame" />
    </joint>
    <link name="camera_color_frame" />
    <joint name="camera_color_optical_joint" type="fixed">
        <origin rpy="-1.57079632679 0.0 -1.57079632679" xyz="0.0 0.0 0.0" />
        <parent link="camera_color_frame" />
        <child link="camera_color_optical_frame" />
    </joint>
    <link name="camera_color_optical_frame" />
    <link name="camera_accel_frame" />
    <link name="camera_accel_optical_frame" />
    <link name="camera_gyro_frame" />
    <link name="camera_gyro_optical_frame" />
    <joint name="camera_accel_joint" type="fixed">
        <origin rpy="0.0 0.0 0.0" xyz="-0.01174 -0.00552 0.0051" />
        <parent link="camera_link" />
        <child link="camera_accel_frame" />
    </joint>
    <joint name="camera_accel_optical_joint" type="fixed">
        <origin rpy="-1.57079632679 0.0 -1.57079632679" xyz="0.0 0.0 0.0" />
        <parent link="camera_accel_frame" />
        <child link="camera_accel_optical_frame" />
    </joint>
    <joint name="camera_gyro_joint" type="fixed">
        <origin rpy="0.0 0.0 0.0" xyz="-0.01174 -0.00552 0.0051" />
        <parent link="camera_link" />
        <child link="camera_gyro_frame" />
    </joint>
    <joint name="camera_gyro_optical_joint" type="fixed">
        <origin rpy="-1.57079632679 0.0 -1.57079632679" xyz="0.0 0.0 0.0" />
        <parent link="camera_gyro_frame" />
        <child link="camera_gyro_optical_frame" />
    </joint>
    <link name="laser">
        
<inertial>
            <origin rpy="0.0 0.0 0.0" xyz="0.0 0.0 -0.000755956127492" />
            <mass value="0.0749979022894" />
            <inertia ixx="0.0" ixy="0.0" ixz="0.0" iyy="0.0" iyz="0.0" izz="0.0" />
        </inertial>

        <visual>
            <origin rpy="0.0 0.0 0.0" xyz="0.0 0.0 0.0" />
            <geometry>
                <mesh filename="package://stretch_description/meshes/laser.STL" />
            </geometry>
            <material name="">
                <color rgba="0.250980392157 0.250980392157 0.250980392157 1.0" />
            </material>
        </visual>
        <collision>
            <origin rpy="0.0 0.0 0.0" xyz="0.0 0.0 0.0" />
            <geometry>
                <mesh filename="package://stretch_description/meshes/laser.STL" />
            </geometry>
        </collision>
    </link>
    <joint name="joint_laser" type="fixed">
        <origin rpy="0.0 0.0 -3.14159265359" xyz="0.000502800000001 0.0 0.1664" />
        <axis xyz="0.0 0.0 0.0" />
        <parent link="base_link" />
        <child link="laser" />
    </joint>
    <link name="respeaker_base">
        
<inertial>
            <origin rpy="0.0 0.0 0.0" xyz="-0.000780828967927 0.00765742173486 -0.00424882983019" />
            <mass value="0.00969129410417" />
            <inertia ixx="8.95656300428e-07" ixy="2.6733074581e-08" ixz="-3.84519793581e-08" iyy="4.04210996171e-07" iyz="3.15533542839e-07" izz="7.08282597118e-07" />
        </inertial>

        <visual>
            <origin rpy="0.0 0.0 0.0" xyz="0.0 0.0 0.0" />
            <geometry>
                <mesh filename="package://stretch_description/meshes/link_respeaker.STL" />
            </geometry>
            <material name="">
                <color rgba="0.792156862745 0.819607843137 0.933333333333 1.0" />
            </material>
        </visual>
        <collision>
            <origin rpy="0.0 0.0 0.0" xyz="0.0 0.0 0.0" />
            <geometry>
                <mesh filename="package://stretch_description/meshes/link_respeaker.STL" />
            </geometry>
        </collision>
    </link>
    <joint name="joint_respeaker" type="fixed">
        <origin rpy="1.5707963268 0.0 3.14159265359" xyz="1.09074743138e-05 1.36992 0.00303572796911" />
        <axis xyz="0.0 0.0 0.0" />
        <parent link="link_mast" />
        <child link="respeaker_base" />
    </joint>
    
<transmission name="trans_joint_gripper_finger_left">
        <type>transmission_interface/SimpleTransmission</type>
        <joint name="joint_gripper_finger_left">
            <hardwareInterface>hardware_interface/EffortJointInterface</hardwareInterface>
        </joint>
        <actuator name="joint_gripper_finger_left_motor">
            <hardwareInterface>hardware_interface/EffortJointInterface</hardwareInterface>
            <mechanicalReduction>1</mechanicalReduction>
        </actuator>
    </transmission>
    <transmission name="trans_joint_gripper_finger_right">
        <type>transmission_interface/SimpleTransmission</type>
        <joint name="joint_gripper_finger_right">
            <hardwareInterface>hardware_interface/EffortJointInterface</hardwareInterface>
        </joint>
        <actuator name="joint_gripper_finger_right_motor">
            <hardwareInterface>hardware_interface/EffortJointInterface</hardwareInterface>
            <mechanicalReduction>1</mechanicalReduction>
        </actuator>
    </transmission>
    <transmission name="trans_joint_right_wheel">
        <type>transmission_interface/SimpleTransmission</type>
        <joint name="joint_right_wheel">
            <hardwareInterface>hardware_interface/EffortJointInterface</hardwareInterface>
        </joint>
        <actuator name="joint_right_wheel_motor">
            <hardwareInterface>hardware_interface/EffortJointInterface</hardwareInterface>
            <mechanicalReduction>1</mechanicalReduction>
        </actuator>
    </transmission>
    <transmission name="trans_joint_left_wheel">
        <type>transmission_interface/SimpleTransmission</type>
        <joint name="joint_left_wheel">
            <hardwareInterface>hardware_interface/EffortJointInterface</hardwareInterface>
        </joint>
        <actuator name="joint_left_wheel_motor">
            <hardwareInterface>hardware_interface/EffortJointInterface</hardwareInterface>
            <mechanicalReduction>1</mechanicalReduction>
        </actuator>
    </transmission>
    <transmission name="trans_joint_lift">
        <type>transmission_interface/SimpleTransmission</type>
        <joint name="joint_lift">
            <hardwareInterface>hardware_interface/EffortJointInterface</hardwareInterface>
        </joint>
        <actuator name="joint_lift_motor">
            <hardwareInterface>hardware_interface/EffortJointInterface</hardwareInterface>
            <mechanicalReduction>1</mechanicalReduction>
        </actuator>
    </transmission>
    <transmission name="trans_joint_arm_l3">
        <type>transmission_interface/SimpleTransmission</type>
        <joint name="joint_arm_l3">
            <hardwareInterface>hardware_interface/EffortJointInterface</hardwareInterface>
        </joint>
        <actuator name="joint_arm_l3_motor">
            <hardwareInterface>hardware_interface/EffortJointInterface</hardwareInterface>
            <mechanicalReduction>1</mechanicalReduction>
        </actuator>
    </transmission>
    <transmission name="trans_joint_arm_l2">
        <type>transmission_interface/SimpleTransmission</type>
        <joint name="joint_arm_l2">
            <hardwareInterface>hardware_interface/EffortJointInterface</hardwareInterface>
        </joint>
        <actuator name="joint_arm_l2_motor">
            <hardwareInterface>hardware_interface/EffortJointInterface</hardwareInterface>
            <mechanicalReduction>1</mechanicalReduction>
        </actuator>
    </transmission>
    <transmission name="trans_joint_arm_l1">
        <type>transmission_interface/SimpleTransmission</type>
        <joint name="joint_arm_l1">
            <hardwareInterface>hardware_interface/EffortJointInterface</hardwareInterface>
        </joint>
        <actuator name="joint_arm_l1_motor">
            <hardwareInterface>hardware_interface/EffortJointInterface</hardwareInterface>
            <mechanicalReduction>1</mechanicalReduction>
        </actuator>
    </transmission>
    <transmission name="trans_joint_arm_l0">
        <type>transmission_interface/SimpleTransmission</type>
        <joint name="joint_arm_l0">
            <hardwareInterface>hardware_interface/EffortJointInterface</hardwareInterface>
        </joint>
        <actuator name="joint_arm_l0_motor">
            <hardwareInterface>hardware_interface/EffortJointInterface</hardwareInterface>
            <mechanicalReduction>1</mechanicalReduction>
        </actuator>
    </transmission>
    <transmission name="trans_joint_wrist_yaw">
        <type>transmission_interface/SimpleTransmission</type>
        <joint name="joint_wrist_yaw">
            <hardwareInterface>hardware_interface/EffortJointInterface</hardwareInterface>
        </joint>
        <actuator name="joint_wrist_yaw_motor">
            <hardwareInterface>hardware_interface/EffortJointInterface</hardwareInterface>
            <mechanicalReduction>1</mechanicalReduction>
        </actuator>
    </transmission>
    <transmission name="trans_joint_head_pan">
        <type>transmission_interface/SimpleTransmission</type>
        <joint name="joint_head_pan">
            <hardwareInterface>hardware_interface/EffortJointInterface</hardwareInterface>
        </joint>
        <actuator name="joint_head_pan_motor">
            <hardwareInterface>hardware_interface/EffortJointInterface</hardwareInterface>
            <mechanicalReduction>1</mechanicalReduction>
        </actuator>
    </transmission>
    <transmission name="trans_joint_head_tilt">
        <type>transmission_interface/SimpleTransmission</type>
        <joint name="joint_head_tilt">
            <hardwareInterface>hardware_interface/EffortJointInterface</hardwareInterface>
        </joint>
        <actuator name="joint_head_tilt_motor">
            <hardwareInterface>hardware_interface/EffortJointInterface</hardwareInterface>
            <mechanicalReduction>1</mechanicalReduction>
        </actuator>
    </transmission>
    <gazebo>
        <plugin name="gazebo_ros_control" filename="libgazebo_ros_control.so">
            <robotNamespace>/</robotNamespace>
        </plugin>
    </gazebo>
</robot>
